Workbook

Sheet Mi avance
A1: Simulador de previaturas · Licenciatura en Geografía
A2: Planilla generada el 02/10/2026 con lo que marcaste en el simulador. Esta hoja se calcula sola: marcá tus unidades curriculares aprobadas en la hoja Unidades curriculares y acá vas a ver tu avance.
A4: Área | B4: Créditos acumulados | C4: Mínimo para el TFG | D4: Te faltan | E4: Avance | F4: Progreso | G4: Estado
A5: Conocimientos Básicos y Generales | B5: =SUMIF('Unidades curriculares'!$C:$C,"Conocimientos Básicos y Generales",'Unidades curriculares'!$F:$F) -> 15 | C5: 60 | D5: =MAX(0,C5-B5) -> 45 | E5: =IF(C5>0,MIN(1,B5/C5),0) -> 0.25 | F5: =REPT("█",ROUND(E5*20,0))&REPT("░",20-ROUND(E5*20,0)) -> █████░░░░░░░░░░░░░░░ | G5: =IF(B5>=C5,"✓ Cumplido","Pendiente") -> Pendiente
A6: Teórico-Metodológico | B6: =SUMIF('Unidades curriculares'!$C:$C,"Teórico-Metodológico",'Unidades curriculares'!$F:$F) -> 12 | C6: 45 | D6: =MAX(0,C6-B6) -> 33 | E6: =IF(C6>0,MIN(1,B6/C6),0) -> 0.26666667 | F6: =REPT("█",ROUND(E6*20,0))&REPT("░",20-ROUND(E6*20,0)) -> █████░░░░░░░░░░░░░░░ | G6: =IF(B6>=C6,"✓ Cumplido","Pendiente") -> Pendiente
A7: Socioespacial | B7: =SUMIF('Unidades curriculares'!$C:$C,"Socioespacial",'Unidades curriculares'!$F:$F) -> 12 | C7: 45 | D7: =MAX(0,C7-B7) -> 33 | E7: =IF(C7>0,MIN(1,B7/C7),0) -> 0.26666667 | F7: =REPT("█",ROUND(E7*20,0))&REPT("░",20-ROUND(E7*20,0)) -> █████░░░░░░░░░░░░░░░ | G7: =IF(B7>=C7,"✓ Cumplido","Pendiente") -> Pendiente
A8: Sistemas Ambientales | B8: =SUMIF('Unidades curriculares'!$C:$C,"Sistemas Ambientales",'Unidades curriculares'!$F:$F) -> 10 | C8: 40 | D8: =MAX(0,C8-B8) -> 30 | E8: =IF(C8>0,MIN(1,B8/C8),0) -> 0.25 | F8: =REPT("█",ROUND(E8*20,0))&REPT("░",20-ROUND(E8*20,0)) -> █████░░░░░░░░░░░░░░░ | G8: =IF(B8>=C8,"✓ Cumplido","Pendiente") -> Pendiente
A9: Tecnologías de la Información Geográfica | B9: =SUMIF('Unidades curriculares'!$C:$C,"Tecnologías de la Información Geográfica",'Unidades curriculares'!$F:$F) -> 24 | C9: 30 | D9: =MAX(0,C9-B9) -> 6 | E9: =IF(C9>0,MIN(1,B9/C9),0) -> 0.8 | F9: =REPT("█",ROUND(E9*20,0))&REPT("░",20-ROUND(E9*20,0)) -> ████████████████░░░░ | G9: =IF(B9>=C9,"✓ Cumplido","Pendiente") -> Pendiente
A10: Extensión u optativas (no tiene mínimo) | B10: =SUMIF('Unidades curriculares'!$C:$C,"Extensión u optativas",'Unidades curriculares'!$F:$F) -> 7
A12: Créditos totales acumulados | B12: =SUM('Unidades curriculares'!$F:$F) -> 80 | C12: 220 | D12: =MAX(0,C12-B12) -> 140 | E12: =IF(C12>0,MIN(1,B12/C12),0) -> 0.36363636 | F12: =REPT("█",ROUND(E12*20,0))&REPT("░",20-ROUND(E12*20,0)) -> ███████░░░░░░░░░░░░░ | G12: =IF(B12>=C12,"✓ Cumplido","Pendiente") -> Pendiente
A13: Créditos de la trayectoria por semestre | B13: =SUM('Unidades curriculares'!$F$6:$F$23) -> 48
A15: Trabajo Final de Grado | B15: =IF(AND(B12>=C12,B5>=C5,B6>=C6,B7>=C7,B8>=C8,B9>=C9),"✓ Ya cumplís los créditos para el Trabajo Final de Grado","Todavía no cumplís los créditos para el Trabajo Final de Grado. Mirá la columna Te faltan.") -> Todavía no cumplís los créditos para el Trabajo Final de Grado. Mirá la columna Te faltan.
A17: Cómo usar esta planilla
A18: 1. Andá a la hoja Unidades curriculares y elegí "Sí" en la columna ¿Aprobada? de cada unidad curricular que aprobaste. Las celdas amarillas son las únicas que tenés que tocar.
A19: 2. La sección 1 es la trayectoria sugerida por semestre. La columna Estado te dice si ya podés cursar cada unidad curricular o qué te falta.
A20: 3. La sección 2 tiene las unidades curriculares sin semestre fijo, que podés ir intercalando. Algunas traen un semestre sugerido como orientación.
A21: 4. Si cursaste algo que no está en la lista, agregalo en la sección 3 con su área y sus créditos.
A22: 5. Esta hoja suma todo automáticamente y muestra cuánto te falta en cada área y en el total.
A24: Los mínimos por área y los 220 créditos totales corresponden al plan de estudios vigente. Esta planilla es una ayuda para planificar y no sustituye la información oficial de Bedelía.

Sheet Unidades curriculares
A1: Unidades curriculares de la Licenciatura en Geografía
A2: Elegí "Sí" en la columna ¿Aprobada? (celdas amarillas) para cada unidad curricular que ya aprobaste. Los créditos obtenidos, el estado de cada unidad curricular y la hoja Mi avance se actualizan solos.
A4: 1. Trayectoria sugerida por semestre
A5: Semestre | B5: Unidad curricular | C5: Área | D5: Créditos | E5: ¿Aprobada? | F5: Créditos obtenidos | G5: Estado | H5: Previaturas
A6: 1 | B6: Introducción y métodos de la geografía | C6: Teórico-Metodológico | D6: 12 | E6: Sí | F6: =IF($E6="Sí",$D6,0) -> 12 | G6: =IF($E6="Sí","✓ Aprobada","Podés cursarla") -> ✓ Aprobada | H6: Sin previaturas
A7: 1 | B7: Cartografía | C7: Tecnologías de la Información Geográfica | D7: 12 | E7: Sí | F7: =IF($E7="Sí",$D7,0) -> 12 | G7: =IF($E7="Sí","✓ Aprobada","Podés cursarla") -> ✓ Aprobada | H7: Sin previaturas
A8: 2 | B8: Fotointerpretación | C8: Tecnologías de la Información Geográfica | D8: 12 | F8: =IF($E8="Sí",$D8,0) -> 0 | G8: =IF($E8="Sí","✓ Aprobada",IF(AND($E$7="Sí"),"Podés cursarla","Falta aprobar: Cartografía")) -> Podés cursarla | H8: Aprobar Cartografía
A9: 2 | B9: Sistemas de Información Geográfica | C9: Tecnologías de la Información Geográfica | D9: 12 | E9: Sí | F9: =IF($E9="Sí",$D9,0) -> 12 | G9: =IF($E9="Sí","✓ Aprobada",IF(AND($E$7="Sí"),"Podés cursarla","Falta aprobar: Cartografía")) -> ✓ Aprobada | H9: Aprobar Cartografía
A10: 2 | B10: Hidrogeografía | C10: Sistemas Ambientales | D10: 8 | F10: =IF($E10="Sí",$D10,0) -> 0 | G10: =IF($E10="Sí","✓ Aprobada",IF(AND($E$7="Sí"),"Podés cursarla","Podés cursarla (se sugiere aprobar antes Cartografía)")) -> Podés cursarla | H10: Sugerida (no obligatoria): Cartografía
A11: 2 | B11: Geografía Humana | C11: Socioespacial | D11: 12 | E11: Sí | F11: =IF($E11="Sí",$D11,0) -> 12 | G11: =IF($E11="Sí","✓ Aprobada","Podés cursarla") -> ✓ Aprobada | H11: Sin previaturas
A12: 3 | B12: Geografía Económica | C12: Socioespacial | D12: 12 | F12: =IF($E12="Sí",$D12,0) -> 0 | G12: =IF($E12="Sí","✓ Aprobada","Podés cursarla") -> Podés cursarla | H12: Sin previaturas
A13: 3 | B13: Geografía Rural | C13: Socioespacial | D13: 12 | F13: =IF($E13="Sí",$D13,0) -> 0 | G13: =IF($E13="Sí","✓ Aprobada",IF('Mi avance'!$B$12>=40,"Podés cursarla","Te faltan "&(40-'Mi avance'!$B$12)&" créditos")) -> Podés cursarla | H13: 40 créditos aprobados
A14: 3 | B14: Geografía Urbana | C14: Socioespacial | D14: 12 | F14: =IF($E14="Sí",$D14,0) -> 0 | G14: =IF($E14="Sí","✓ Aprobada",IF('Mi avance'!$B$12>=40,"Podés cursarla","Te faltan "&(40-'Mi avance'!$B$12)&" créditos")) -> Podés cursarla | H14: 40 créditos aprobados
A15: 4 | B15: Biogeografía | C15: Sistemas Ambientales | D15: 10 | F15: =IF($E15="Sí",$D15,0) -> 0 | G15: =IF($E15="Sí","✓ Aprobada",IF('Mi avance'!$B$12>=90,"Podés cursarla","Te faltan "&(90-'Mi avance'!$B$12)&" créditos")) -> Te faltan 10 créditos | H15: 90 créditos aprobados
A16: 4 | B16: Evaluación de recursos naturales e impacto ambiental | C16: Sistemas Ambientales | D16: 12 | F16: =IF($E16="Sí",$D16,0) -> 0 | G16: =IF($E16="Sí","✓ Aprobada",IF(AND($E$10="Sí"),"Podés cursarla","Falta aprobar: Hidrogeografía")) -> Falta aprobar: Hidrogeografía | H16: Aprobar Hidrogeografía
A17: 4 | B17: Teledetección | C17: Tecnologías de la Información Geográfica | D17: 12 | F17: =IF($E17="Sí",$D17,0) -> 0 | G17: =IF($E17="Sí","✓ Aprobada",IF(AND($E$7="Sí"),"Podés cursarla","Falta aprobar: Cartografía")) -> Podés cursarla | H17: Aprobar Cartografía
A18: 5 | B18: Planificación territorial sostenible | C18: Teórico-Metodológico | D18: 12 | F18: =IF($E18="Sí",$D18,0) -> 0 | G18: =IF($E18="Sí","✓ Aprobada",IF('Mi avance'!$B$12>=180,"Podés cursarla","Te faltan "&(180-'Mi avance'!$B$12)&" créditos")) -> Te faltan 100 créditos | H18: 180 créditos aprobados
A19: 6 | B19: Geografía del Uruguay | C19: Socioespacial | D19: 12 | F19: =IF($E19="Sí",$D19,0) -> 0 | G19: =IF($E19="Sí","✓ Aprobada",IF('Mi avance'!$B$12>=180,"Podés cursarla","Te faltan "&(180-'Mi avance'!$B$12)&" créditos")) -> Te faltan 100 créditos | H19: 180 créditos aprobados
A20: 6 | B20: Análisis Espacial | C20: Teórico-Metodológico | D20: 12 | F20: =IF($E20="Sí",$D20,0) -> 0 | G20: =IF($E20="Sí","✓ Aprobada",IF('Mi avance'!$B$12>=180,"Podés cursarla","Te faltan "&(180-'Mi avance'!$B$12)&" créditos")) -> Te faltan 100 créditos | H20: 180 créditos aprobados
A21: 7 | B21: Metodología de la investigación geográfica | C21: Teórico-Metodológico | D21: 12 | F21: =IF($E21="Sí",$D21,0) -> 0 | G21: =IF($E21="Sí","✓ Aprobada",IF('Mi avance'!$B$12>=100,"Podés cursarla","Te faltan "&(100-'Mi avance'!$B$12)&" créditos")) -> Te faltan 20 créditos | H21: 100 créditos aprobados
A22: 7 | B22: Diseño de investigación geográfica | C22: Teórico-Metodológico | D22: 8 | F22: =IF($E22="Sí",$D22,0) -> 0 | G22: =IF($E22="Sí","✓ Aprobada",IF('Mi avance'!$B$12>=200,"Podés cursarla","Te faltan "&(200-'Mi avance'!$B$12)&" créditos")) -> Te faltan 120 créditos | H22: 200 créditos aprobados
A23: 8 | B23: Trabajo Final de Grado | C23: Teórico-Metodológico | D23: 40 | F23: =IF($E23="Sí",$D23,0) -> 0 | G23: =IF($E23="Sí","✓ Aprobada",IF(AND('Mi avance'!$B$12>=220,'Mi avance'!$B$5>='Mi avance'!$C$5,'Mi avance'!$B$6>='Mi avance'!$C$6,'Mi avance'!$B$7>='Mi avance'!$C$7,'Mi avance'!$B$8>='Mi avance'!$C$8,'Mi avance'!$B$9>='Mi avance'!$C$9),"Podés cursarla","Todavía no: revisá los mínimos en la hoja Mi avance")) -> Todavía no: revisá los mínimos en la hoja Mi avance | H23: 220 créditos y los mínimos de cada área
A25: 2. Otras unidades curriculares (sin semestre fijo, se pueden intercalar)
A26: Semestre sugerido | B26: Unidad curricular | C26: Área | D26: Créditos | E26: ¿Aprobada? | F26: Créditos obtenidos | G26: Dictada por | H26: Observaciones
A27: 1 | B27: Alfabetización en Información 1 | C27: Conocimientos Básicos y Generales | D27: 1 | F27: =IF($E27="Sí",$D27,0) -> 0 | G27: Centro de Documentación Científica y Biblioteca
A28: 1 | B28: Inglés I | C28: Conocimientos Básicos y Generales | D28: 5 | E28: Sí | F28: =IF($E28="Sí",$D28,0) -> 5 | G28: Decanato
A29: 1 | B29: Matemática 1 | C29: Conocimientos Básicos y Generales | D29: 12 | F29: =IF($E29="Sí",$D29,0) -> 0 | G29: Centro de Matemática
A30: 2 | B30: Alfabetización en Información II | C30: Conocimientos Básicos y Generales | D30: 1 | F30: =IF($E30="Sí",$D30,0) -> 0 | G30: Centro de Documentación Científica y Biblioteca
A31: 2 | B31: Inglés II | C31: Conocimientos Básicos y Generales | D31: 5 | F31: =IF($E31="Sí",$D31,0) -> 0 | G31: Decanato
A32: 3 | B32: Geografía Económica (Complemento para egresados de Formación Docente) | C32: Socioespacial | D32: 4 | F32: =IF($E32="Sí",$D32,0) -> 0 | G32: Departamento de Geografía
B33: Agua y Salud | C33: Sistemas Ambientales | D33: 10 | E33: Sí | F33: =IF($E33="Sí",$D33,0) -> 10 | G33: Instituto de Ecología y Ciencias Ambientales
B34: Análisis de Datos para Ciencias | C34: Conocimientos Básicos y Generales | D34: 12 | F34: =IF($E34="Sí",$D34,0) -> 0 | G34: Centro de Matemática
B35: Cianobacterias y Eutrofización | C35: Extensión u optativas | D35: 7 | F35: =IF($E35="Sí",$D35,0) -> 0 | G35: Instituto de Ecología y Ciencias Ambientales | H35: Suma al total, no a un área mínima
B36: Ciencia del suelo | C36: Sistemas Ambientales | D36: 12 | F36: =IF($E36="Sí",$D36,0) -> 0 | G36: UNCIEP / Instituto de Ecología y Ciencias Ambientales
B37: Climatología para Biogeociencias | C37: Conocimientos Básicos y Generales | D37: 12 | F37: =IF($E37="Sí",$D37,0) -> 0 | G37: Instituto de Física
B38: Ecosistemas costero-marinos | C38: Sistemas Ambientales | D38: 6 | F38: =IF($E38="Sí",$D38,0) -> 0 | G38: Instituto de Ecología y Ciencias Ambientales
B39: EFI - Ecoparque Idea Vilariño: memoria, territorio y comunidad | C39: Extensión u optativas | D39: 11 | F39: =IF($E39="Sí",$D39,0) -> 0 | G39: Unidad de Extensión | H39: Suma al total, no a un área mínima
B40: EFI - Monitoreo participativo del río Santa Lucía | C40: Extensión u optativas | D40: 11 | F40: =IF($E40="Sí",$D40,0) -> 0 | G40: Unidad de Extensión | H40: Suma al total, no a un área mínima
B41: EFI Ciencia en Territorio: un laboratorio de saberes compartidos | C41: Extensión u optativas | D41: 6 | F41: =IF($E41="Sí",$D41,0) -> 0 | G41: Unidad de Extensión e Instituto de Biología | H41: Suma al total, no a un área mínima
B42: EFI Memorias y justicia ambiental: un abordaje transdisciplinario | C42: Extensión u optativas | D42: 10 | F42: =IF($E42="Sí",$D42,0) -> 0 | G42: Unidad de Extensión y Núcleo Interdisciplinario | H42: Suma al total, no a un área mínima
...
